Traceback (most recent call last):
  File "main.py", line 107, in <module>
    handle_connection(conn, function_map)
  File "main.py", line 61, in handle_connection
    msg = msg.decode().strip()
UnicodeDecodeError: 'utf-8' codec can't decode byte 0xa3 in position 37: invalid start byte
Traceback (most recent call last):
  File "main.py", line 92, in <module>
    s.bind(("0.0.0.0", port))
OSError: [Errno 98] Address already in use
Traceback (most recent call last):
  File "main.py", line 92, in <module>
    s.bind(("0.0.0.0", port))
OSError: [Errno 98] Address already in use
Traceback (most recent call last):
  File "main.py", line 92, in <module>
    s.bind(("0.0.0.0", port))
OSError: [Errno 98] Address already in use
Traceback (most recent call last):
  File "main.py", line 92, in <module>
    s.bind(("0.0.0.0", port))
OSError: [Errno 98] Address already in use
